Watching for file changes with StatReloader
index page access
"GET / HTTP/1.1" 200 72
index page access
"GET / HTTP/1.1" 200 72
Watching for file changes with StatReloader
Internal Server Error: /
Traceback (most recent call last):
  File "/home/applepie/.local/lib/python3.10/site-packages/django/core/handlers/exception.py", line 55, in inner
    response = get_response(request)
  File "/home/applepie/.local/lib/python3.10/site-packages/django/core/handlers/base.py", line 197, in _get_response
    response = wrapped_callback(request, *callback_args, **callback_kwargs)
  File "/home/applepie/.local/lib/python3.10/site-packages/django/views/generic/base.py", line 104, in view
    return self.dispatch(request, *args, **kwargs)
  File "/home/applepie/.local/lib/python3.10/site-packages/django/views/generic/base.py", line 143, in dispatch
    return handler(request, *args, **kwargs)
  File "/home/applepie/STUDENT/Django/Django_hw2/myproject/myapp/views.py", line 17, in get
    return render(request, 'index.html', context)
  File "/home/applepie/.local/lib/python3.10/site-packages/django/shortcuts.py", line 25, in render
    content = loader.render_to_string(template_name, context, request, using=using)
  File "/home/applepie/.local/lib/python3.10/site-packages/django/template/loader.py", line 61, in render_to_string
    template = get_template(template_name, using=using)
  File "/home/applepie/.local/lib/python3.10/site-packages/django/template/loader.py", line 19, in get_template
    raise TemplateDoesNotExist(template_name, chain=chain)
django.template.exceptions.TemplateDoesNotExist: index.html
"GET / HTTP/1.1" 500 88420
/home/applepie/STUDENT/Django/Django_hw2/myproject/myapp/views.py changed, reloading.
Watching for file changes with StatReloader
"GET / HTTP/1.1" 200 250
/home/applepie/STUDENT/Django/Django_hw2/myproject/myapp/views.py changed, reloading.
Watching for file changes with StatReloader
/home/applepie/STUDENT/Django/Django_hw2/myproject/myapp/urls.py changed, reloading.
Watching for file changes with StatReloader
Watching for file changes with StatReloader
"GET / HTTP/1.1" 200 458
"GET /list HTTP/1.1" 301 0
"GET /list/ HTTP/1.1" 200 1456
Internal Server Error: /
Traceback (most recent call last):
  File "/home/applepie/.local/lib/python3.10/site-packages/django/template/backends/django.py", line 61, in render
    return self.template.render(context)
  File "/home/applepie/.local/lib/python3.10/site-packages/django/template/base.py", line 171, in render
    return self._render(context)
  File "/home/applepie/.local/lib/python3.10/site-packages/django/template/base.py", line 163, in _render
    return self.nodelist.render(context)
  File "/home/applepie/.local/lib/python3.10/site-packages/django/template/base.py", line 1000, in render
    return SafeString("".join([node.render_annotated(context) for node in self]))
  File "/home/applepie/.local/lib/python3.10/site-packages/django/template/base.py", line 1000, in <listcomp>
    return SafeString("".join([node.render_annotated(context) for node in self]))
  File "/home/applepie/.local/lib/python3.10/site-packages/django/template/base.py", line 961, in render_annotated
    return self.render(context)
  File "/home/applepie/.local/lib/python3.10/site-packages/django/template/loader_tags.py", line 134, in render
    compiled_parent = self.get_parent(context)
  File "/home/applepie/.local/lib/python3.10/site-packages/django/template/loader_tags.py", line 131, in get_parent
    return self.find_template(parent, context)
  File "/home/applepie/.local/lib/python3.10/site-packages/django/template/loader_tags.py", line 109, in find_template
    template, origin = context.template.engine.find_template(
  File "/home/applepie/.local/lib/python3.10/site-packages/django/template/engine.py", line 163, in find_template
    raise TemplateDoesNotExist(name, tried=tried)
django.template.exceptions.TemplateDoesNotExist: myapp3/base.html

The above exception was the direct cause of the following exception:

Traceback (most recent call last):
  File "/home/applepie/.local/lib/python3.10/site-packages/django/core/handlers/exception.py", line 55, in inner
    response = get_response(request)
  File "/home/applepie/.local/lib/python3.10/site-packages/django/core/handlers/base.py", line 197, in _get_response
    response = wrapped_callback(request, *callback_args, **callback_kwargs)
  File "/home/applepie/.local/lib/python3.10/site-packages/django/views/generic/base.py", line 104, in view
    return self.dispatch(request, *args, **kwargs)
  File "/home/applepie/.local/lib/python3.10/site-packages/django/views/generic/base.py", line 143, in dispatch
    return handler(request, *args, **kwargs)
  File "/home/applepie/STUDENT/Django/Django_hw2/myproject/myapp/views.py", line 17, in get
    return render(request, 'myapp/index.html', context)
  File "/home/applepie/.local/lib/python3.10/site-packages/django/shortcuts.py", line 25, in render
    content = loader.render_to_string(template_name, context, request, using=using)
  File "/home/applepie/.local/lib/python3.10/site-packages/django/template/loader.py", line 62, in render_to_string
    return template.render(context, request)
  File "/home/applepie/.local/lib/python3.10/site-packages/django/template/backends/django.py", line 63, in render
    reraise(exc, self.backend)
  File "/home/applepie/.local/lib/python3.10/site-packages/django/template/backends/django.py", line 84, in reraise
    raise new from exc
django.template.exceptions.TemplateDoesNotExist: myapp3/base.html
"GET / HTTP/1.1" 500 137895
Internal Server Error: /
Traceback (most recent call last):
  File "/home/applepie/.local/lib/python3.10/site-packages/django/template/backends/django.py", line 61, in render
    return self.template.render(context)
  File "/home/applepie/.local/lib/python3.10/site-packages/django/template/base.py", line 171, in render
    return self._render(context)
  File "/home/applepie/.local/lib/python3.10/site-packages/django/template/base.py", line 163, in _render
    return self.nodelist.render(context)
  File "/home/applepie/.local/lib/python3.10/site-packages/django/template/base.py", line 1000, in render
    return SafeString("".join([node.render_annotated(context) for node in self]))
  File "/home/applepie/.local/lib/python3.10/site-packages/django/template/base.py", line 1000, in <listcomp>
    return SafeString("".join([node.render_annotated(context) for node in self]))
  File "/home/applepie/.local/lib/python3.10/site-packages/django/template/base.py", line 961, in render_annotated
    return self.render(context)
  File "/home/applepie/.local/lib/python3.10/site-packages/django/template/loader_tags.py", line 134, in render
    compiled_parent = self.get_parent(context)
  File "/home/applepie/.local/lib/python3.10/site-packages/django/template/loader_tags.py", line 131, in get_parent
    return self.find_template(parent, context)
  File "/home/applepie/.local/lib/python3.10/site-packages/django/template/loader_tags.py", line 109, in find_template
    template, origin = context.template.engine.find_template(
  File "/home/applepie/.local/lib/python3.10/site-packages/django/template/engine.py", line 163, in find_template
    raise TemplateDoesNotExist(name, tried=tried)
django.template.exceptions.TemplateDoesNotExist: myapp3/base.html

The above exception was the direct cause of the following exception:

Traceback (most recent call last):
  File "/home/applepie/.local/lib/python3.10/site-packages/django/core/handlers/exception.py", line 55, in inner
    response = get_response(request)
  File "/home/applepie/.local/lib/python3.10/site-packages/django/core/handlers/base.py", line 197, in _get_response
    response = wrapped_callback(request, *callback_args, **callback_kwargs)
  File "/home/applepie/.local/lib/python3.10/site-packages/django/views/generic/base.py", line 104, in view
    return self.dispatch(request, *args, **kwargs)
  File "/home/applepie/.local/lib/python3.10/site-packages/django/views/generic/base.py", line 143, in dispatch
    return handler(request, *args, **kwargs)
  File "/home/applepie/STUDENT/Django/Django_hw2/myproject/myapp/views.py", line 17, in get
    return render(request, 'myapp/index.html', context)
  File "/home/applepie/.local/lib/python3.10/site-packages/django/shortcuts.py", line 25, in render
    content = loader.render_to_string(template_name, context, request, using=using)
  File "/home/applepie/.local/lib/python3.10/site-packages/django/template/loader.py", line 62, in render_to_string
    return template.render(context, request)
  File "/home/applepie/.local/lib/python3.10/site-packages/django/template/backends/django.py", line 63, in render
    reraise(exc, self.backend)
  File "/home/applepie/.local/lib/python3.10/site-packages/django/template/backends/django.py", line 84, in reraise
    raise new from exc
django.template.exceptions.TemplateDoesNotExist: myapp3/base.html
"GET / HTTP/1.1" 500 137895
"GET / HTTP/1.1" 200 404
"GET /list/ HTTP/1.1" 200 1238
/home/applepie/STUDENT/Django/Django_hw2/myproject/myproject/settings.py changed, reloading.
Watching for file changes with StatReloader
Internal Server Error: /list/
Traceback (most recent call last):
  File "/home/applepie/.local/lib/python3.10/site-packages/django/template/backends/django.py", line 61, in render
    return self.template.render(context)
  File "/home/applepie/.local/lib/python3.10/site-packages/django/template/base.py", line 171, in render
    return self._render(context)
  File "/home/applepie/.local/lib/python3.10/site-packages/django/template/base.py", line 163, in _render
    return self.nodelist.render(context)
  File "/home/applepie/.local/lib/python3.10/site-packages/django/template/base.py", line 1000, in render
    return SafeString("".join([node.render_annotated(context) for node in self]))
  File "/home/applepie/.local/lib/python3.10/site-packages/django/template/base.py", line 1000, in <listcomp>
    return SafeString("".join([node.render_annotated(context) for node in self]))
  File "/home/applepie/.local/lib/python3.10/site-packages/django/template/base.py", line 961, in render_annotated
    return self.render(context)
  File "/home/applepie/.local/lib/python3.10/site-packages/django/template/loader_tags.py", line 134, in render
    compiled_parent = self.get_parent(context)
  File "/home/applepie/.local/lib/python3.10/site-packages/django/template/loader_tags.py", line 131, in get_parent
    return self.find_template(parent, context)
  File "/home/applepie/.local/lib/python3.10/site-packages/django/template/loader_tags.py", line 109, in find_template
    template, origin = context.template.engine.find_template(
  File "/home/applepie/.local/lib/python3.10/site-packages/django/template/engine.py", line 163, in find_template
    raise TemplateDoesNotExist(name, tried=tried)
django.template.exceptions.TemplateDoesNotExist: base.html

The above exception was the direct cause of the following exception:

Traceback (most recent call last):
  File "/home/applepie/.local/lib/python3.10/site-packages/django/core/handlers/exception.py", line 55, in inner
    response = get_response(request)
  File "/home/applepie/.local/lib/python3.10/site-packages/django/core/handlers/base.py", line 197, in _get_response
    response = wrapped_callback(request, *callback_args, **callback_kwargs)
  File "/home/applepie/STUDENT/Django/Django_hw2/myproject/myapp/views.py", line 42, in view_for
    return render(request, 'myapp/index.html', context)
  File "/home/applepie/.local/lib/python3.10/site-packages/django/shortcuts.py", line 25, in render
    content = loader.render_to_string(template_name, context, request, using=using)
  File "/home/applepie/.local/lib/python3.10/site-packages/django/template/loader.py", line 62, in render_to_string
    return template.render(context, request)
  File "/home/applepie/.local/lib/python3.10/site-packages/django/template/backends/django.py", line 63, in render
    reraise(exc, self.backend)
  File "/home/applepie/.local/lib/python3.10/site-packages/django/template/backends/django.py", line 84, in reraise
    raise new from exc
django.template.exceptions.TemplateDoesNotExist: base.html
"GET /list/ HTTP/1.1" 500 135240
Watching for file changes with StatReloader
Internal Server Error: /list/
Traceback (most recent call last):
  File "/home/applepie/.local/lib/python3.10/site-packages/django/template/backends/django.py", line 61, in render
    return self.template.render(context)
  File "/home/applepie/.local/lib/python3.10/site-packages/django/template/base.py", line 171, in render
    return self._render(context)
  File "/home/applepie/.local/lib/python3.10/site-packages/django/template/base.py", line 163, in _render
    return self.nodelist.render(context)
  File "/home/applepie/.local/lib/python3.10/site-packages/django/template/base.py", line 1000, in render
    return SafeString("".join([node.render_annotated(context) for node in self]))
  File "/home/applepie/.local/lib/python3.10/site-packages/django/template/base.py", line 1000, in <listcomp>
    return SafeString("".join([node.render_annotated(context) for node in self]))
  File "/home/applepie/.local/lib/python3.10/site-packages/django/template/base.py", line 961, in render_annotated
    return self.render(context)
  File "/home/applepie/.local/lib/python3.10/site-packages/django/template/loader_tags.py", line 134, in render
    compiled_parent = self.get_parent(context)
  File "/home/applepie/.local/lib/python3.10/site-packages/django/template/loader_tags.py", line 131, in get_parent
    return self.find_template(parent, context)
  File "/home/applepie/.local/lib/python3.10/site-packages/django/template/loader_tags.py", line 109, in find_template
    template, origin = context.template.engine.find_template(
  File "/home/applepie/.local/lib/python3.10/site-packages/django/template/engine.py", line 163, in find_template
    raise TemplateDoesNotExist(name, tried=tried)
django.template.exceptions.TemplateDoesNotExist: base.html

The above exception was the direct cause of the following exception:

Traceback (most recent call last):
  File "/home/applepie/.local/lib/python3.10/site-packages/django/core/handlers/exception.py", line 55, in inner
    response = get_response(request)
  File "/home/applepie/.local/lib/python3.10/site-packages/django/core/handlers/base.py", line 197, in _get_response
    response = wrapped_callback(request, *callback_args, **callback_kwargs)
  File "/home/applepie/STUDENT/Django/Django_hw2/myproject/myapp/views.py", line 42, in view_for
    return render(request, 'myapp/index.html', context)
  File "/home/applepie/.local/lib/python3.10/site-packages/django/shortcuts.py", line 25, in render
    content = loader.render_to_string(template_name, context, request, using=using)
  File "/home/applepie/.local/lib/python3.10/site-packages/django/template/loader.py", line 62, in render_to_string
    return template.render(context, request)
  File "/home/applepie/.local/lib/python3.10/site-packages/django/template/backends/django.py", line 63, in render
    reraise(exc, self.backend)
  File "/home/applepie/.local/lib/python3.10/site-packages/django/template/backends/django.py", line 84, in reraise
    raise new from exc
django.template.exceptions.TemplateDoesNotExist: base.html
"GET /list/ HTTP/1.1" 500 135240
Internal Server Error: /list/
Traceback (most recent call last):
  File "/home/applepie/.local/lib/python3.10/site-packages/django/template/backends/django.py", line 61, in render
    return self.template.render(context)
  File "/home/applepie/.local/lib/python3.10/site-packages/django/template/base.py", line 171, in render
    return self._render(context)
  File "/home/applepie/.local/lib/python3.10/site-packages/django/template/base.py", line 163, in _render
    return self.nodelist.render(context)
  File "/home/applepie/.local/lib/python3.10/site-packages/django/template/base.py", line 1000, in render
    return SafeString("".join([node.render_annotated(context) for node in self]))
  File "/home/applepie/.local/lib/python3.10/site-packages/django/template/base.py", line 1000, in <listcomp>
    return SafeString("".join([node.render_annotated(context) for node in self]))
  File "/home/applepie/.local/lib/python3.10/site-packages/django/template/base.py", line 961, in render_annotated
    return self.render(context)
  File "/home/applepie/.local/lib/python3.10/site-packages/django/template/loader_tags.py", line 134, in render
    compiled_parent = self.get_parent(context)
  File "/home/applepie/.local/lib/python3.10/site-packages/django/template/loader_tags.py", line 131, in get_parent
    return self.find_template(parent, context)
  File "/home/applepie/.local/lib/python3.10/site-packages/django/template/loader_tags.py", line 109, in find_template
    template, origin = context.template.engine.find_template(
  File "/home/applepie/.local/lib/python3.10/site-packages/django/template/engine.py", line 163, in find_template
    raise TemplateDoesNotExist(name, tried=tried)
django.template.exceptions.TemplateDoesNotExist: base.html

The above exception was the direct cause of the following exception:

Traceback (most recent call last):
  File "/home/applepie/.local/lib/python3.10/site-packages/django/core/handlers/exception.py", line 55, in inner
    response = get_response(request)
  File "/home/applepie/.local/lib/python3.10/site-packages/django/core/handlers/base.py", line 197, in _get_response
    response = wrapped_callback(request, *callback_args, **callback_kwargs)
  File "/home/applepie/STUDENT/Django/Django_hw2/myproject/myapp/views.py", line 42, in view_for
    return render(request, 'myapp/index.html', context)
  File "/home/applepie/.local/lib/python3.10/site-packages/django/shortcuts.py", line 25, in render
    content = loader.render_to_string(template_name, context, request, using=using)
  File "/home/applepie/.local/lib/python3.10/site-packages/django/template/loader.py", line 62, in render_to_string
    return template.render(context, request)
  File "/home/applepie/.local/lib/python3.10/site-packages/django/template/backends/django.py", line 63, in render
    reraise(exc, self.backend)
  File "/home/applepie/.local/lib/python3.10/site-packages/django/template/backends/django.py", line 84, in reraise
    raise new from exc
django.template.exceptions.TemplateDoesNotExist: base.html
"GET /list/ HTTP/1.1" 500 135240
Internal Server Error: /list/
Traceback (most recent call last):
  File "/home/applepie/.local/lib/python3.10/site-packages/django/template/backends/django.py", line 61, in render
    return self.template.render(context)
  File "/home/applepie/.local/lib/python3.10/site-packages/django/template/base.py", line 171, in render
    return self._render(context)
  File "/home/applepie/.local/lib/python3.10/site-packages/django/template/base.py", line 163, in _render
    return self.nodelist.render(context)
  File "/home/applepie/.local/lib/python3.10/site-packages/django/template/base.py", line 1000, in render
    return SafeString("".join([node.render_annotated(context) for node in self]))
  File "/home/applepie/.local/lib/python3.10/site-packages/django/template/base.py", line 1000, in <listcomp>
    return SafeString("".join([node.render_annotated(context) for node in self]))
  File "/home/applepie/.local/lib/python3.10/site-packages/django/template/base.py", line 961, in render_annotated
    return self.render(context)
  File "/home/applepie/.local/lib/python3.10/site-packages/django/template/loader_tags.py", line 134, in render
    compiled_parent = self.get_parent(context)
  File "/home/applepie/.local/lib/python3.10/site-packages/django/template/loader_tags.py", line 131, in get_parent
    return self.find_template(parent, context)
  File "/home/applepie/.local/lib/python3.10/site-packages/django/template/loader_tags.py", line 109, in find_template
    template, origin = context.template.engine.find_template(
  File "/home/applepie/.local/lib/python3.10/site-packages/django/template/engine.py", line 163, in find_template
    raise TemplateDoesNotExist(name, tried=tried)
django.template.exceptions.TemplateDoesNotExist: base.html

The above exception was the direct cause of the following exception:

Traceback (most recent call last):
  File "/home/applepie/.local/lib/python3.10/site-packages/django/core/handlers/exception.py", line 55, in inner
    response = get_response(request)
  File "/home/applepie/.local/lib/python3.10/site-packages/django/core/handlers/base.py", line 197, in _get_response
    response = wrapped_callback(request, *callback_args, **callback_kwargs)
  File "/home/applepie/STUDENT/Django/Django_hw2/myproject/myapp/views.py", line 42, in view_for
    return render(request, 'myapp/index.html', context)
  File "/home/applepie/.local/lib/python3.10/site-packages/django/shortcuts.py", line 25, in render
    content = loader.render_to_string(template_name, context, request, using=using)
  File "/home/applepie/.local/lib/python3.10/site-packages/django/template/loader.py", line 62, in render_to_string
    return template.render(context, request)
  File "/home/applepie/.local/lib/python3.10/site-packages/django/template/backends/django.py", line 63, in render
    reraise(exc, self.backend)
  File "/home/applepie/.local/lib/python3.10/site-packages/django/template/backends/django.py", line 84, in reraise
    raise new from exc
django.template.exceptions.TemplateDoesNotExist: base.html
"GET /list/ HTTP/1.1" 500 135240
Watching for file changes with StatReloader
"GET /list/ HTTP/1.1" 200 1238
/home/applepie/STUDENT/Django/Django_hw2/myproject/myapp/models.py changed, reloading.
Watching for file changes with StatReloader
/home/applepie/STUDENT/Django/Django_hw2/myproject/myapp/urls.py changed, reloading.
Watching for file changes with StatReloader
/home/applepie/STUDENT/Django/Django_hw2/myproject/myapp/urls.py changed, reloading.
Watching for file changes with StatReloader
/home/applepie/STUDENT/Django/Django_hw2/myproject/myapp/views.py changed, reloading.
Watching for file changes with StatReloader
/home/applepie/STUDENT/Django/Django_hw2/myproject/myapp/views.py changed, reloading.
Watching for file changes with StatReloader
Internal Server Error: /user_orders/19
Traceback (most recent call last):
  File "/home/applepie/.local/lib/python3.10/site-packages/django/core/handlers/exception.py", line 55, in inner
    response = get_response(request)
  File "/home/applepie/.local/lib/python3.10/site-packages/django/core/handlers/base.py", line 197, in _get_response
    response = wrapped_callback(request, *callback_args, **callback_kwargs)
  File "/home/applepie/STUDENT/Django/Django_hw2/myproject/myapp/views.py", line 48, in user_orders
    orders = Order.objects.filter(user=user)
  File "/home/applepie/.local/lib/python3.10/site-packages/django/db/models/manager.py", line 87, in manager_method
    return getattr(self.get_queryset(), name)(*args, **kwargs)
  File "/home/applepie/.local/lib/python3.10/site-packages/django/db/models/query.py", line 1476, in filter
    return self._filter_or_exclude(False, args, kwargs)
  File "/home/applepie/.local/lib/python3.10/site-packages/django/db/models/query.py", line 1494, in _filter_or_exclude
    clone._filter_or_exclude_inplace(negate, args, kwargs)
  File "/home/applepie/.local/lib/python3.10/site-packages/django/db/models/query.py", line 1501, in _filter_or_exclude_inplace
    self._query.add_q(Q(*args, **kwargs))
  File "/home/applepie/.local/lib/python3.10/site-packages/django/db/models/sql/query.py", line 1613, in add_q
    clause, _ = self._add_q(q_object, self.used_aliases)
  File "/home/applepie/.local/lib/python3.10/site-packages/django/db/models/sql/query.py", line 1645, in _add_q
    child_clause, needed_inner = self.build_filter(
  File "/home/applepie/.local/lib/python3.10/site-packages/django/db/models/sql/query.py", line 1495, in build_filter
    lookups, parts, reffed_expression = self.solve_lookup_type(arg, summarize)
  File "/home/applepie/.local/lib/python3.10/site-packages/django/db/models/sql/query.py", line 1307, in solve_lookup_type
    _, field, _, lookup_parts = self.names_to_path(lookup_splitted, self.get_meta())
  File "/home/applepie/.local/lib/python3.10/site-packages/django/db/models/sql/query.py", line 1772, in names_to_path
    raise FieldError(
django.core.exceptions.FieldError: Cannot resolve keyword 'user' into field. Choices are: customer, customer_id, date_ordered, id, products, total_price
"GET /user_orders/19 HTTP/1.1" 500 111481
Not Found: /favicon.ico
Internal Server Error: /user_orders/19
Traceback (most recent call last):
  File "/home/applepie/.local/lib/python3.10/site-packages/django/core/handlers/exception.py", line 55, in inner
    response = get_response(request)
  File "/home/applepie/.local/lib/python3.10/site-packages/django/core/handlers/base.py", line 197, in _get_response
    response = wrapped_callback(request, *callback_args, **callback_kwargs)
  File "/home/applepie/STUDENT/Django/Django_hw2/myproject/myapp/views.py", line 48, in user_orders
    orders = Order.objects.filter(user=user)
  File "/home/applepie/.local/lib/python3.10/site-packages/django/db/models/manager.py", line 87, in manager_method
    return getattr(self.get_queryset(), name)(*args, **kwargs)
  File "/home/applepie/.local/lib/python3.10/site-packages/django/db/models/query.py", line 1476, in filter
    return self._filter_or_exclude(False, args, kwargs)
  File "/home/applepie/.local/lib/python3.10/site-packages/django/db/models/query.py", line 1494, in _filter_or_exclude
    clone._filter_or_exclude_inplace(negate, args, kwargs)
  File "/home/applepie/.local/lib/python3.10/site-packages/django/db/models/query.py", line 1501, in _filter_or_exclude_inplace
    self._query.add_q(Q(*args, **kwargs))
  File "/home/applepie/.local/lib/python3.10/site-packages/django/db/models/sql/query.py", line 1613, in add_q
    clause, _ = self._add_q(q_object, self.used_aliases)
  File "/home/applepie/.local/lib/python3.10/site-packages/django/db/models/sql/query.py", line 1645, in _add_q
    child_clause, needed_inner = self.build_filter(
  File "/home/applepie/.local/lib/python3.10/site-packages/django/db/models/sql/query.py", line 1495, in build_filter
    lookups, parts, reffed_expression = self.solve_lookup_type(arg, summarize)
  File "/home/applepie/.local/lib/python3.10/site-packages/django/db/models/sql/query.py", line 1307, in solve_lookup_type
    _, field, _, lookup_parts = self.names_to_path(lookup_splitted, self.get_meta())
  File "/home/applepie/.local/lib/python3.10/site-packages/django/db/models/sql/query.py", line 1772, in names_to_path
    raise FieldError(
django.core.exceptions.FieldError: Cannot resolve keyword 'user' into field. Choices are: customer, customer_id, date_ordered, id, products, total_price
"GET /user_orders/19 HTTP/1.1" 500 111481
Watching for file changes with StatReloader
Internal Server Error: /user_orders/19
Traceback (most recent call last):
  File "/home/applepie/.local/lib/python3.10/site-packages/django/core/handlers/exception.py", line 55, in inner
    response = get_response(request)
  File "/home/applepie/.local/lib/python3.10/site-packages/django/core/handlers/base.py", line 197, in _get_response
    response = wrapped_callback(request, *callback_args, **callback_kwargs)
  File "/home/applepie/STUDENT/Django/Django_hw2/myproject/myapp/views.py", line 48, in user_orders
    orders = Order.objects.filter(user=user)
  File "/home/applepie/.local/lib/python3.10/site-packages/django/db/models/manager.py", line 87, in manager_method
    return getattr(self.get_queryset(), name)(*args, **kwargs)
  File "/home/applepie/.local/lib/python3.10/site-packages/django/db/models/query.py", line 1476, in filter
    return self._filter_or_exclude(False, args, kwargs)
  File "/home/applepie/.local/lib/python3.10/site-packages/django/db/models/query.py", line 1494, in _filter_or_exclude
    clone._filter_or_exclude_inplace(negate, args, kwargs)
  File "/home/applepie/.local/lib/python3.10/site-packages/django/db/models/query.py", line 1501, in _filter_or_exclude_inplace
    self._query.add_q(Q(*args, **kwargs))
  File "/home/applepie/.local/lib/python3.10/site-packages/django/db/models/sql/query.py", line 1613, in add_q
    clause, _ = self._add_q(q_object, self.used_aliases)
  File "/home/applepie/.local/lib/python3.10/site-packages/django/db/models/sql/query.py", line 1645, in _add_q
    child_clause, needed_inner = self.build_filter(
  File "/home/applepie/.local/lib/python3.10/site-packages/django/db/models/sql/query.py", line 1495, in build_filter
    lookups, parts, reffed_expression = self.solve_lookup_type(arg, summarize)
  File "/home/applepie/.local/lib/python3.10/site-packages/django/db/models/sql/query.py", line 1307, in solve_lookup_type
    _, field, _, lookup_parts = self.names_to_path(lookup_splitted, self.get_meta())
  File "/home/applepie/.local/lib/python3.10/site-packages/django/db/models/sql/query.py", line 1772, in names_to_path
    raise FieldError(
django.core.exceptions.FieldError: Cannot resolve keyword 'user' into field. Choices are: customer, customer_id, date_ordered, id, products, total_price
"GET /user_orders/19 HTTP/1.1" 500 111481
Internal Server Error: /user_orders/19
Traceback (most recent call last):
  File "/home/applepie/.local/lib/python3.10/site-packages/django/core/handlers/exception.py", line 55, in inner
    response = get_response(request)
  File "/home/applepie/.local/lib/python3.10/site-packages/django/core/handlers/base.py", line 197, in _get_response
    response = wrapped_callback(request, *callback_args, **callback_kwargs)
  File "/home/applepie/STUDENT/Django/Django_hw2/myproject/myapp/views.py", line 48, in user_orders
    orders = Order.objects.filter(user=user)
  File "/home/applepie/.local/lib/python3.10/site-packages/django/db/models/manager.py", line 87, in manager_method
    return getattr(self.get_queryset(), name)(*args, **kwargs)
  File "/home/applepie/.local/lib/python3.10/site-packages/django/db/models/query.py", line 1476, in filter
    return self._filter_or_exclude(False, args, kwargs)
  File "/home/applepie/.local/lib/python3.10/site-packages/django/db/models/query.py", line 1494, in _filter_or_exclude
    clone._filter_or_exclude_inplace(negate, args, kwargs)
  File "/home/applepie/.local/lib/python3.10/site-packages/django/db/models/query.py", line 1501, in _filter_or_exclude_inplace
    self._query.add_q(Q(*args, **kwargs))
  File "/home/applepie/.local/lib/python3.10/site-packages/django/db/models/sql/query.py", line 1613, in add_q
    clause, _ = self._add_q(q_object, self.used_aliases)
  File "/home/applepie/.local/lib/python3.10/site-packages/django/db/models/sql/query.py", line 1645, in _add_q
    child_clause, needed_inner = self.build_filter(
  File "/home/applepie/.local/lib/python3.10/site-packages/django/db/models/sql/query.py", line 1495, in build_filter
    lookups, parts, reffed_expression = self.solve_lookup_type(arg, summarize)
  File "/home/applepie/.local/lib/python3.10/site-packages/django/db/models/sql/query.py", line 1307, in solve_lookup_type
    _, field, _, lookup_parts = self.names_to_path(lookup_splitted, self.get_meta())
  File "/home/applepie/.local/lib/python3.10/site-packages/django/db/models/sql/query.py", line 1772, in names_to_path
    raise FieldError(
django.core.exceptions.FieldError: Cannot resolve keyword 'user' into field. Choices are: customer, customer_id, date_ordered, id, products, total_price
"GET /user_orders/19 HTTP/1.1" 500 111481
Internal Server Error: /user_orders/19
Traceback (most recent call last):
  File "/home/applepie/.local/lib/python3.10/site-packages/django/core/handlers/exception.py", line 55, in inner
    response = get_response(request)
  File "/home/applepie/.local/lib/python3.10/site-packages/django/core/handlers/base.py", line 197, in _get_response
    response = wrapped_callback(request, *callback_args, **callback_kwargs)
  File "/home/applepie/STUDENT/Django/Django_hw2/myproject/myapp/views.py", line 48, in user_orders
    orders = Order.objects.filter(user=user)
  File "/home/applepie/.local/lib/python3.10/site-packages/django/db/models/manager.py", line 87, in manager_method
    return getattr(self.get_queryset(), name)(*args, **kwargs)
  File "/home/applepie/.local/lib/python3.10/site-packages/django/db/models/query.py", line 1476, in filter
    return self._filter_or_exclude(False, args, kwargs)
  File "/home/applepie/.local/lib/python3.10/site-packages/django/db/models/query.py", line 1494, in _filter_or_exclude
    clone._filter_or_exclude_inplace(negate, args, kwargs)
  File "/home/applepie/.local/lib/python3.10/site-packages/django/db/models/query.py", line 1501, in _filter_or_exclude_inplace
    self._query.add_q(Q(*args, **kwargs))
  File "/home/applepie/.local/lib/python3.10/site-packages/django/db/models/sql/query.py", line 1613, in add_q
    clause, _ = self._add_q(q_object, self.used_aliases)
  File "/home/applepie/.local/lib/python3.10/site-packages/django/db/models/sql/query.py", line 1645, in _add_q
    child_clause, needed_inner = self.build_filter(
  File "/home/applepie/.local/lib/python3.10/site-packages/django/db/models/sql/query.py", line 1495, in build_filter
    lookups, parts, reffed_expression = self.solve_lookup_type(arg, summarize)
  File "/home/applepie/.local/lib/python3.10/site-packages/django/db/models/sql/query.py", line 1307, in solve_lookup_type
    _, field, _, lookup_parts = self.names_to_path(lookup_splitted, self.get_meta())
  File "/home/applepie/.local/lib/python3.10/site-packages/django/db/models/sql/query.py", line 1772, in names_to_path
    raise FieldError(
django.core.exceptions.FieldError: Cannot resolve keyword 'user' into field. Choices are: customer, customer_id, date_ordered, id, products, total_price
"GET /user_orders/19 HTTP/1.1" 500 111481
Internal Server Error: /user_orders/19
Traceback (most recent call last):
  File "/home/applepie/.local/lib/python3.10/site-packages/django/core/handlers/exception.py", line 55, in inner
    response = get_response(request)
  File "/home/applepie/.local/lib/python3.10/site-packages/django/core/handlers/base.py", line 197, in _get_response
    response = wrapped_callback(request, *callback_args, **callback_kwargs)
  File "/home/applepie/STUDENT/Django/Django_hw2/myproject/myapp/views.py", line 48, in user_orders
    orders = Order.objects.filter(user=user)
  File "/home/applepie/.local/lib/python3.10/site-packages/django/db/models/manager.py", line 87, in manager_method
    return getattr(self.get_queryset(), name)(*args, **kwargs)
  File "/home/applepie/.local/lib/python3.10/site-packages/django/db/models/query.py", line 1476, in filter
    return self._filter_or_exclude(False, args, kwargs)
  File "/home/applepie/.local/lib/python3.10/site-packages/django/db/models/query.py", line 1494, in _filter_or_exclude
    clone._filter_or_exclude_inplace(negate, args, kwargs)
  File "/home/applepie/.local/lib/python3.10/site-packages/django/db/models/query.py", line 1501, in _filter_or_exclude_inplace
    self._query.add_q(Q(*args, **kwargs))
  File "/home/applepie/.local/lib/python3.10/site-packages/django/db/models/sql/query.py", line 1613, in add_q
    clause, _ = self._add_q(q_object, self.used_aliases)
  File "/home/applepie/.local/lib/python3.10/site-packages/django/db/models/sql/query.py", line 1645, in _add_q
    child_clause, needed_inner = self.build_filter(
  File "/home/applepie/.local/lib/python3.10/site-packages/django/db/models/sql/query.py", line 1495, in build_filter
    lookups, parts, reffed_expression = self.solve_lookup_type(arg, summarize)
  File "/home/applepie/.local/lib/python3.10/site-packages/django/db/models/sql/query.py", line 1307, in solve_lookup_type
    _, field, _, lookup_parts = self.names_to_path(lookup_splitted, self.get_meta())
  File "/home/applepie/.local/lib/python3.10/site-packages/django/db/models/sql/query.py", line 1772, in names_to_path
    raise FieldError(
django.core.exceptions.FieldError: Cannot resolve keyword 'user' into field. Choices are: customer, customer_id, date_ordered, id, products, total_price
"GET /user_orders/19 HTTP/1.1" 500 111481
Internal Server Error: /user_orders/19
Traceback (most recent call last):
  File "/home/applepie/.local/lib/python3.10/site-packages/django/core/handlers/exception.py", line 55, in inner
    response = get_response(request)
  File "/home/applepie/.local/lib/python3.10/site-packages/django/core/handlers/base.py", line 197, in _get_response
    response = wrapped_callback(request, *callback_args, **callback_kwargs)
  File "/home/applepie/STUDENT/Django/Django_hw2/myproject/myapp/views.py", line 48, in user_orders
    orders = Order.objects.filter(user=user)
  File "/home/applepie/.local/lib/python3.10/site-packages/django/db/models/manager.py", line 87, in manager_method
    return getattr(self.get_queryset(), name)(*args, **kwargs)
  File "/home/applepie/.local/lib/python3.10/site-packages/django/db/models/query.py", line 1476, in filter
    return self._filter_or_exclude(False, args, kwargs)
  File "/home/applepie/.local/lib/python3.10/site-packages/django/db/models/query.py", line 1494, in _filter_or_exclude
    clone._filter_or_exclude_inplace(negate, args, kwargs)
  File "/home/applepie/.local/lib/python3.10/site-packages/django/db/models/query.py", line 1501, in _filter_or_exclude_inplace
    self._query.add_q(Q(*args, **kwargs))
  File "/home/applepie/.local/lib/python3.10/site-packages/django/db/models/sql/query.py", line 1613, in add_q
    clause, _ = self._add_q(q_object, self.used_aliases)
  File "/home/applepie/.local/lib/python3.10/site-packages/django/db/models/sql/query.py", line 1645, in _add_q
    child_clause, needed_inner = self.build_filter(
  File "/home/applepie/.local/lib/python3.10/site-packages/django/db/models/sql/query.py", line 1495, in build_filter
    lookups, parts, reffed_expression = self.solve_lookup_type(arg, summarize)
  File "/home/applepie/.local/lib/python3.10/site-packages/django/db/models/sql/query.py", line 1307, in solve_lookup_type
    _, field, _, lookup_parts = self.names_to_path(lookup_splitted, self.get_meta())
  File "/home/applepie/.local/lib/python3.10/site-packages/django/db/models/sql/query.py", line 1772, in names_to_path
    raise FieldError(
django.core.exceptions.FieldError: Cannot resolve keyword 'user' into field. Choices are: customer, customer_id, date_ordered, id, products, total_price
"GET /user_orders/19 HTTP/1.1" 500 111481
Watching for file changes with StatReloader
Internal Server Error: /user_orders/19
Traceback (most recent call last):
  File "/home/applepie/.local/lib/python3.10/site-packages/django/core/handlers/exception.py", line 55, in inner
    response = get_response(request)
  File "/home/applepie/.local/lib/python3.10/site-packages/django/core/handlers/base.py", line 197, in _get_response
    response = wrapped_callback(request, *callback_args, **callback_kwargs)
  File "/home/applepie/STUDENT/Django/Django_hw2/myproject/myapp/views.py", line 48, in user_orders
    orders = Order.objects.filter(user=user)
  File "/home/applepie/.local/lib/python3.10/site-packages/django/db/models/manager.py", line 87, in manager_method
    return getattr(self.get_queryset(), name)(*args, **kwargs)
  File "/home/applepie/.local/lib/python3.10/site-packages/django/db/models/query.py", line 1476, in filter
    return self._filter_or_exclude(False, args, kwargs)
  File "/home/applepie/.local/lib/python3.10/site-packages/django/db/models/query.py", line 1494, in _filter_or_exclude
    clone._filter_or_exclude_inplace(negate, args, kwargs)
  File "/home/applepie/.local/lib/python3.10/site-packages/django/db/models/query.py", line 1501, in _filter_or_exclude_inplace
    self._query.add_q(Q(*args, **kwargs))
  File "/home/applepie/.local/lib/python3.10/site-packages/django/db/models/sql/query.py", line 1613, in add_q
    clause, _ = self._add_q(q_object, self.used_aliases)
  File "/home/applepie/.local/lib/python3.10/site-packages/django/db/models/sql/query.py", line 1645, in _add_q
    child_clause, needed_inner = self.build_filter(
  File "/home/applepie/.local/lib/python3.10/site-packages/django/db/models/sql/query.py", line 1495, in build_filter
    lookups, parts, reffed_expression = self.solve_lookup_type(arg, summarize)
  File "/home/applepie/.local/lib/python3.10/site-packages/django/db/models/sql/query.py", line 1307, in solve_lookup_type
    _, field, _, lookup_parts = self.names_to_path(lookup_splitted, self.get_meta())
  File "/home/applepie/.local/lib/python3.10/site-packages/django/db/models/sql/query.py", line 1772, in names_to_path
    raise FieldError(
django.core.exceptions.FieldError: Cannot resolve keyword 'user' into field. Choices are: customer, customer_id, date_ordered, id, products, total_price
"GET /user_orders/19 HTTP/1.1" 500 111481
/home/applepie/STUDENT/Django/Django_hw2/myproject/myapp/views.py changed, reloading.
Watching for file changes with StatReloader
"GET /user_orders/19 HTTP/1.1" 200 438
"GET /user_orders/19 HTTP/1.1" 200 438
"GET /user_orders/19 HTTP/1.1" 200 443
Internal Server Error: /user_orders/19
Traceback (most recent call last):
  File "/home/applepie/.local/lib/python3.10/site-packages/django/core/handlers/exception.py", line 55, in inner
    response = get_response(request)
  File "/home/applepie/.local/lib/python3.10/site-packages/django/core/handlers/base.py", line 197, in _get_response
    response = wrapped_callback(request, *callback_args, **callback_kwargs)
  File "/home/applepie/STUDENT/Django/Django_hw2/myproject/myapp/views.py", line 50, in user_orders
    return render(request, 'myapp/user_orders.html', {'user': user, 'orders': orders})
  File "/home/applepie/.local/lib/python3.10/site-packages/django/shortcuts.py", line 25, in render
    content = loader.render_to_string(template_name, context, request, using=using)
  File "/home/applepie/.local/lib/python3.10/site-packages/django/template/loader.py", line 62, in render_to_string
    return template.render(context, request)
  File "/home/applepie/.local/lib/python3.10/site-packages/django/template/backends/django.py", line 61, in render
    return self.template.render(context)
  File "/home/applepie/.local/lib/python3.10/site-packages/django/template/base.py", line 171, in render
    return self._render(context)
  File "/home/applepie/.local/lib/python3.10/site-packages/django/template/base.py", line 163, in _render
    return self.nodelist.render(context)
  File "/home/applepie/.local/lib/python3.10/site-packages/django/template/base.py", line 1000, in render
    return SafeString("".join([node.render_annotated(context) for node in self]))
  File "/home/applepie/.local/lib/python3.10/site-packages/django/template/base.py", line 1000, in <listcomp>
    return SafeString("".join([node.render_annotated(context) for node in self]))
  File "/home/applepie/.local/lib/python3.10/site-packages/django/template/base.py", line 961, in render_annotated
    return self.render(context)
  File "/home/applepie/.local/lib/python3.10/site-packages/django/template/loader_tags.py", line 159, in render
    return compiled_parent._render(context)
  File "/home/applepie/.local/lib/python3.10/site-packages/django/template/base.py", line 163, in _render
    return self.nodelist.render(context)
  File "/home/applepie/.local/lib/python3.10/site-packages/django/template/base.py", line 1000, in render
    return SafeString("".join([node.render_annotated(context) for node in self]))
  File "/home/applepie/.local/lib/python3.10/site-packages/django/template/base.py", line 1000, in <listcomp>
    return SafeString("".join([node.render_annotated(context) for node in self]))
  File "/home/applepie/.local/lib/python3.10/site-packages/django/template/base.py", line 961, in render_annotated
    return self.render(context)
  File "/home/applepie/.local/lib/python3.10/site-packages/django/template/loader_tags.py", line 65, in render
    result = block.nodelist.render(context)
  File "/home/applepie/.local/lib/python3.10/site-packages/django/template/base.py", line 1000, in render
    return SafeString("".join([node.render_annotated(context) for node in self]))
  File "/home/applepie/.local/lib/python3.10/site-packages/django/template/base.py", line 1000, in <listcomp>
    return SafeString("".join([node.render_annotated(context) for node in self]))
  File "/home/applepie/.local/lib/python3.10/site-packages/django/template/base.py", line 961, in render_annotated
    return self.render(context)
  File "/home/applepie/.local/lib/python3.10/site-packages/django/template/defaulttags.py", line 242, in render
    nodelist.append(node.render_annotated(context))
  File "/home/applepie/.local/lib/python3.10/site-packages/django/template/base.py", line 961, in render_annotated
    return self.render(context)
  File "/home/applepie/.local/lib/python3.10/site-packages/django/template/defaulttags.py", line 197, in render
    values = list(values)
TypeError: 'ManyRelatedManager' object is not iterable
"GET /user_orders/19 HTTP/1.1" 500 158950
Internal Server Error: /user_orders/19
Traceback (most recent call last):
  File "/home/applepie/.local/lib/python3.10/site-packages/django/core/handlers/exception.py", line 55, in inner
    response = get_response(request)
  File "/home/applepie/.local/lib/python3.10/site-packages/django/core/handlers/base.py", line 197, in _get_response
    response = wrapped_callback(request, *callback_args, **callback_kwargs)
  File "/home/applepie/STUDENT/Django/Django_hw2/myproject/myapp/views.py", line 50, in user_orders
    return render(request, 'myapp/user_orders.html', {'user': user, 'orders': orders})
  File "/home/applepie/.local/lib/python3.10/site-packages/django/shortcuts.py", line 25, in render
    content = loader.render_to_string(template_name, context, request, using=using)
  File "/home/applepie/.local/lib/python3.10/site-packages/django/template/loader.py", line 62, in render_to_string
    return template.render(context, request)
  File "/home/applepie/.local/lib/python3.10/site-packages/django/template/backends/django.py", line 61, in render
    return self.template.render(context)
  File "/home/applepie/.local/lib/python3.10/site-packages/django/template/base.py", line 171, in render
    return self._render(context)
  File "/home/applepie/.local/lib/python3.10/site-packages/django/template/base.py", line 163, in _render
    return self.nodelist.render(context)
  File "/home/applepie/.local/lib/python3.10/site-packages/django/template/base.py", line 1000, in render
    return SafeString("".join([node.render_annotated(context) for node in self]))
  File "/home/applepie/.local/lib/python3.10/site-packages/django/template/base.py", line 1000, in <listcomp>
    return SafeString("".join([node.render_annotated(context) for node in self]))
  File "/home/applepie/.local/lib/python3.10/site-packages/django/template/base.py", line 961, in render_annotated
    return self.render(context)
  File "/home/applepie/.local/lib/python3.10/site-packages/django/template/loader_tags.py", line 159, in render
    return compiled_parent._render(context)
  File "/home/applepie/.local/lib/python3.10/site-packages/django/template/base.py", line 163, in _render
    return self.nodelist.render(context)
  File "/home/applepie/.local/lib/python3.10/site-packages/django/template/base.py", line 1000, in render
    return SafeString("".join([node.render_annotated(context) for node in self]))
  File "/home/applepie/.local/lib/python3.10/site-packages/django/template/base.py", line 1000, in <listcomp>
    return SafeString("".join([node.render_annotated(context) for node in self]))
  File "/home/applepie/.local/lib/python3.10/site-packages/django/template/base.py", line 961, in render_annotated
    return self.render(context)
  File "/home/applepie/.local/lib/python3.10/site-packages/django/template/loader_tags.py", line 65, in render
    result = block.nodelist.render(context)
  File "/home/applepie/.local/lib/python3.10/site-packages/django/template/base.py", line 1000, in render
    return SafeString("".join([node.render_annotated(context) for node in self]))
  File "/home/applepie/.local/lib/python3.10/site-packages/django/template/base.py", line 1000, in <listcomp>
    return SafeString("".join([node.render_annotated(context) for node in self]))
  File "/home/applepie/.local/lib/python3.10/site-packages/django/template/base.py", line 961, in render_annotated
    return self.render(context)
  File "/home/applepie/.local/lib/python3.10/site-packages/django/template/defaulttags.py", line 242, in render
    nodelist.append(node.render_annotated(context))
  File "/home/applepie/.local/lib/python3.10/site-packages/django/template/base.py", line 961, in render_annotated
    return self.render(context)
  File "/home/applepie/.local/lib/python3.10/site-packages/django/template/defaulttags.py", line 197, in render
    values = list(values)
TypeError: 'ManyRelatedManager' object is not iterable
"GET /user_orders/19 HTTP/1.1" 500 158950
Internal Server Error: /user_orders/19
Traceback (most recent call last):
  File "/home/applepie/.local/lib/python3.10/site-packages/django/template/base.py", line 502, in parse
    compile_func = self.tags[command]
KeyError: 'endblock'

During handling of the above exception, another exception occurred:

Traceback (most recent call last):
  File "/home/applepie/.local/lib/python3.10/site-packages/django/core/handlers/exception.py", line 55, in inner
    response = get_response(request)
  File "/home/applepie/.local/lib/python3.10/site-packages/django/core/handlers/base.py", line 197, in _get_response
    response = wrapped_callback(request, *callback_args, **callback_kwargs)
  File "/home/applepie/STUDENT/Django/Django_hw2/myproject/myapp/views.py", line 50, in user_orders
    return render(request, 'myapp/user_orders.html', {'user': user, 'orders': orders})
  File "/home/applepie/.local/lib/python3.10/site-packages/django/shortcuts.py", line 25, in render
    content = loader.render_to_string(template_name, context, request, using=using)
  File "/home/applepie/.local/lib/python3.10/site-packages/django/template/loader.py", line 61, in render_to_string
    template = get_template(template_name, using=using)
  File "/home/applepie/.local/lib/python3.10/site-packages/django/template/loader.py", line 15, in get_template
    return engine.get_template(template_name)
  File "/home/applepie/.local/lib/python3.10/site-packages/django/template/backends/django.py", line 33, in get_template
    return Template(self.engine.get_template(template_name), self)
  File "/home/applepie/.local/lib/python3.10/site-packages/django/template/engine.py", line 177, in get_template
    template, origin = self.find_template(template_name)
  File "/home/applepie/.local/lib/python3.10/site-packages/django/template/engine.py", line 159, in find_template
    template = loader.get_template(name, skip=skip)
  File "/home/applepie/.local/lib/python3.10/site-packages/django/template/loaders/cached.py", line 57, in get_template
    template = super().get_template(template_name, skip)
  File "/home/applepie/.local/lib/python3.10/site-packages/django/template/loaders/base.py", line 28, in get_template
    return Template(
  File "/home/applepie/.local/lib/python3.10/site-packages/django/template/base.py", line 154, in __init__
    self.nodelist = self.compile_nodelist()
  File "/home/applepie/.local/lib/python3.10/site-packages/django/template/base.py", line 196, in compile_nodelist
    return parser.parse()
  File "/home/applepie/.local/lib/python3.10/site-packages/django/template/base.py", line 510, in parse
    raise self.error(token, e)
  File "/home/applepie/.local/lib/python3.10/site-packages/django/template/base.py", line 508, in parse
    compiled_result = compile_func(self, token)
  File "/home/applepie/.local/lib/python3.10/site-packages/django/template/loader_tags.py", line 295, in do_extends
    nodelist = parser.parse()
  File "/home/applepie/.local/lib/python3.10/site-packages/django/template/base.py", line 510, in parse
    raise self.error(token, e)
  File "/home/applepie/.local/lib/python3.10/site-packages/django/template/base.py", line 508, in parse
    compiled_result = compile_func(self, token)
  File "/home/applepie/.local/lib/python3.10/site-packages/django/template/loader_tags.py", line 234, in do_block
    nodelist = parser.parse(("endblock",))
  File "/home/applepie/.local/lib/python3.10/site-packages/django/template/base.py", line 510, in parse
    raise self.error(token, e)
  File "/home/applepie/.local/lib/python3.10/site-packages/django/template/base.py", line 508, in parse
    compiled_result = compile_func(self, token)
  File "/home/applepie/.local/lib/python3.10/site-packages/django/template/defaulttags.py", line 861, in do_for
    nodelist_loop = parser.parse(
  File "/home/applepie/.local/lib/python3.10/site-packages/django/template/base.py", line 504, in parse
    self.invalid_block_tag(token, command, parse_until)
  File "/home/applepie/.local/lib/python3.10/site-packages/django/template/base.py", line 555, in invalid_block_tag
    raise self.error(
django.template.exceptions.TemplateSyntaxError: Invalid block tag on line 10: 'endblock', expected 'empty' or 'endfor'. Did you forget to register or load this tag?
"GET /user_orders/19 HTTP/1.1" 500 177763
"GET /user_orders/19 HTTP/1.1" 200 552
"GET /user_orders/19 HTTP/1.1" 200 552
/home/applepie/STUDENT/Django/Django_hw2/myproject/myapp/views.py changed, reloading.
Watching for file changes with StatReloader
"GET /user_orders/19 HTTP/1.1" 200 552
"GET /user_orders/19 HTTP/1.1" 200 552
/home/applepie/STUDENT/Django/Django_hw2/myproject/myapp/views.py changed, reloading.
Watching for file changes with StatReloader
"GET /user_orders/19 HTTP/1.1" 200 552
/home/applepie/STUDENT/Django/Django_hw2/myproject/myapp/views.py changed, reloading.
Watching for file changes with StatReloader
"GET /user_orders/19 HTTP/1.1" 200 1800
"GET /user_orders/20 HTTP/1.1" 200 1439
Not Found: /favicon.ico
"GET /user_orders/21 HTTP/1.1" 200 1443
Not Found: /favicon.ico
"GET /user_orders/22 HTTP/1.1" 200 1447
Not Found: /favicon.ico
"GET /user_orders/23 HTTP/1.1" 200 1452
Not Found: /favicon.ico
Not Found: /user_orders/24
"GET /user_orders/24 HTTP/1.1" 404 2965
Not Found: /favicon.ico
"GET /user_orders/18 HTTP/1.1" 200 1798
Not Found: /favicon.ico
/home/applepie/STUDENT/Django/Django_hw2/myproject/myapp/urls.py changed, reloading.
Watching for file changes with StatReloader
/home/applepie/STUDENT/Django/Django_hw2/myproject/myapp/views.py changed, reloading.
Watching for file changes with StatReloader
/home/applepie/STUDENT/Django/Django_hw2/myproject/myapp/views.py changed, reloading.
Watching for file changes with StatReloader
/home/applepie/STUDENT/Django/Django_hw2/myproject/myapp/views.py changed, reloading.
Watching for file changes with StatReloader
Internal Server Error: /sort_products/18
Traceback (most recent call last):
  File "/home/applepie/.local/lib/python3.10/site-packages/django/core/handlers/exception.py", line 55, in inner
    response = get_response(request)
  File "/home/applepie/.local/lib/python3.10/site-packages/django/core/handlers/base.py", line 197, in _get_response
    response = wrapped_callback(request, *callback_args, **callback_kwargs)
  File "/home/applepie/STUDENT/Django/Django_hw2/myproject/myapp/views.py", line 21, in sort_products
    today = timezone.now()
AttributeError: type object 'datetime.timezone' has no attribute 'now'
"GET /sort_products/18 HTTP/1.1" 500 65329
Not Found: /favicon.ico
/home/applepie/STUDENT/Django/Django_hw2/myproject/myapp/views.py changed, reloading.
Watching for file changes with StatReloader
Internal Server Error: /sort_products/18
Traceback (most recent call last):
  File "/home/applepie/.local/lib/python3.10/site-packages/django/core/handlers/exception.py", line 55, in inner
    response = get_response(request)
  File "/home/applepie/.local/lib/python3.10/site-packages/django/core/handlers/base.py", line 197, in _get_response
    response = wrapped_callback(request, *callback_args, **callback_kwargs)
  File "/home/applepie/STUDENT/Django/Django_hw2/myproject/myapp/views.py", line 42, in sort_products
    return render(request, 'user_orders.html', context)
  File "/home/applepie/.local/lib/python3.10/site-packages/django/shortcuts.py", line 25, in render
    content = loader.render_to_string(template_name, context, request, using=using)
  File "/home/applepie/.local/lib/python3.10/site-packages/django/template/loader.py", line 61, in render_to_string
    template = get_template(template_name, using=using)
  File "/home/applepie/.local/lib/python3.10/site-packages/django/template/loader.py", line 19, in get_template
    raise TemplateDoesNotExist(template_name, chain=chain)
django.template.exceptions.TemplateDoesNotExist: user_orders.html
"GET /sort_products/18 HTTP/1.1" 500 88399
Internal Server Error: /sort_products/18
Traceback (most recent call last):
  File "/home/applepie/.local/lib/python3.10/site-packages/django/core/handlers/exception.py", line 55, in inner
    response = get_response(request)
  File "/home/applepie/.local/lib/python3.10/site-packages/django/core/handlers/base.py", line 197, in _get_response
    response = wrapped_callback(request, *callback_args, **callback_kwargs)
  File "/home/applepie/STUDENT/Django/Django_hw2/myproject/myapp/views.py", line 42, in sort_products
    return render(request, 'sort_products.html', context)
  File "/home/applepie/.local/lib/python3.10/site-packages/django/shortcuts.py", line 25, in render
    content = loader.render_to_string(template_name, context, request, using=using)
  File "/home/applepie/.local/lib/python3.10/site-packages/django/template/loader.py", line 61, in render_to_string
    template = get_template(template_name, using=using)
  File "/home/applepie/.local/lib/python3.10/site-packages/django/template/loader.py", line 19, in get_template
    raise TemplateDoesNotExist(template_name, chain=chain)
django.template.exceptions.TemplateDoesNotExist: user_orders.html
"GET /sort_products/18 HTTP/1.1" 500 88403
/home/applepie/STUDENT/Django/Django_hw2/myproject/myapp/views.py changed, reloading.
Watching for file changes with StatReloader
Internal Server Error: /sort_products/18
Traceback (most recent call last):
  File "/home/applepie/.local/lib/python3.10/site-packages/django/core/handlers/exception.py", line 55, in inner
    response = get_response(request)
  File "/home/applepie/.local/lib/python3.10/site-packages/django/core/handlers/base.py", line 197, in _get_response
    response = wrapped_callback(request, *callback_args, **callback_kwargs)
  File "/home/applepie/STUDENT/Django/Django_hw2/myproject/myapp/views.py", line 42, in sort_products
    return render(request, 'sort_products.html', context)
  File "/home/applepie/.local/lib/python3.10/site-packages/django/shortcuts.py", line 25, in render
    content = loader.render_to_string(template_name, context, request, using=using)
  File "/home/applepie/.local/lib/python3.10/site-packages/django/template/loader.py", line 61, in render_to_string
    template = get_template(template_name, using=using)
  File "/home/applepie/.local/lib/python3.10/site-packages/django/template/loader.py", line 19, in get_template
    raise TemplateDoesNotExist(template_name, chain=chain)
django.template.exceptions.TemplateDoesNotExist: sort_products.html
"GET /sort_products/18 HTTP/1.1" 500 88435
Internal Server Error: /sort_products/18
Traceback (most recent call last):
  File "/home/applepie/.local/lib/python3.10/site-packages/django/core/handlers/exception.py", line 55, in inner
    response = get_response(request)
  File "/home/applepie/.local/lib/python3.10/site-packages/django/core/handlers/base.py", line 197, in _get_response
    response = wrapped_callback(request, *callback_args, **callback_kwargs)
  File "/home/applepie/STUDENT/Django/Django_hw2/myproject/myapp/views.py", line 42, in sort_products
    return render(request, 'myapp/sort_products.html', context)
  File "/home/applepie/.local/lib/python3.10/site-packages/django/shortcuts.py", line 25, in render
    content = loader.render_to_string(template_name, context, request, using=using)
  File "/home/applepie/.local/lib/python3.10/site-packages/django/template/loader.py", line 61, in render_to_string
    template = get_template(template_name, using=using)
  File "/home/applepie/.local/lib/python3.10/site-packages/django/template/loader.py", line 19, in get_template
    raise TemplateDoesNotExist(template_name, chain=chain)
django.template.exceptions.TemplateDoesNotExist: sort_products.html
"GET /sort_products/18 HTTP/1.1" 500 88447
/home/applepie/STUDENT/Django/Django_hw2/myproject/myapp/views.py changed, reloading.
Watching for file changes with StatReloader
"GET /sort_products/18 HTTP/1.1" 200 1370
"GET /sort_products/20 HTTP/1.1" 200 953
Not Found: /favicon.ico
"GET /user_orders/20 HTTP/1.1" 200 1439
